<?xml version="1.0" encoding="utf-8"?>
<!-- This URDF was automatically created by SolidWorks to URDF Exporter! Originally created by Stephen Brawner (brawner@gmail.com) 
     Commit Version: 1.6.0-4-g7f85cfe  Build Version: 1.6.7995.38578
     For more information, please see http://wiki.ros.org/sw_urdf_exporter -->
<robot
  name="erob170iv6">
  <link
    name="base_link">
    <inertial>
      <origin
        xyz="0.056404 0.00025815 -3.2887E-06"
        rpy="0 0 0" />
      <mass
        value="0.60238" />
      <inertia
        ixx="0.0024424"
        ixy="-3.0768E-07"
        ixz="-6.2418E-08"
        iyy="0.0014757"
        iyz="-2.8497E-07"
        izz="0.0014686" />
    </inertial>
    <visual>
      <origin
        xyz="0 0 0"
        rpy="0 0 0" />
      <geometry>
        <mesh
          filename="package://erob_description/meshes/erob170iv6/base_link.STL" />
      </geometry>
      <material
        name="">
        <color
          rgba="0.627 0.627 0.627 1" />
      </material>
    </visual>
    <collision>
      <origin
        xyz="0 0 0"
        rpy="0 0 0" />
      <geometry>
        <mesh
          filename="package://erob_description/meshes/erob170iv6/base_link.STL" />
      </geometry> 
    </collision>
  </link>
  <link
    name="fixed_link">
    <inertial>
      <origin
        xyz="0.10639 4.3871E-13 -3.4231E-11"
        rpy="0 0 0" />
      <mass
        value="0.3784" />
      <inertia
        ixx="0.0019011"
        ixy="1.298E-15"
        ixz="-9.6397E-14"
        iyy="0.00098736"
        iyz="6.818E-09"
        izz="0.00098738" />
    </inertial>
    <visual>
      <origin
        xyz="0 0 0"
        rpy="0 0 0" />
      <geometry>
        <mesh
          filename="package://erob_description/meshes/erob170iv6/fixed_link.STL" />
      </geometry>
      <material
        name="">
        <color
          rgba="0.1 0.1 0.1 1" />
      </material>
    </visual>
    <collision>
      <origin
        xyz="0 0 0"
        rpy="0 0 0" />
      <geometry>
        <mesh
          filename="package://erob_description/meshes/erob170iv6/fixed_link.STL" />
      </geometry>
    </collision>
  </link>
  <joint
    name="fixed_joint"
    type="fixed">
    <origin
      xyz="0 0 0"
      rpy="0 0 0" />
    <parent
      link="base_link" />
    <child
      link="fixed_link" />
    <axis
      xyz="0 0 0" />
  </joint>
  <link
    name="revolute_link">
    <inertial>
      <origin
        xyz="-0.012582 6.1119E-05 -9.0731E-05"
        rpy="0 0 0" />
      <mass
        value="0.18567" />
      <inertia
        ixx="0.00049966"
        ixy="-7.5121E-09"
        ixz="1.1991E-08"
        iyy="0.00030649"
        iyz="-5.7433E-07"
        izz="0.00030697" />
    </inertial>
    <visual>
      <origin
        xyz="0 0 0"
        rpy="0 0 0" />
      <geometry>
        <mesh
          filename="package://erob_description/meshes/erob170iv6/revolute_link.STL" />
      </geometry>
      <material
        name="">
        <color
          rgba="0.863 0.863 0.941 1" />
      </material>
    </visual>
    <collision>
      <origin
        xyz="0 0 0"
        rpy="0 0 0" />
      <geometry>
        <mesh
          filename="package://erob_description/meshes/erob170iv6/revolute_link.STL" />
      </geometry>
    </collision>
  </link>
  <joint
    name="revolute_joint"
    type="revolute">
    <origin
      xyz="0.144 0 0"
      rpy="0 0 0" />
    <parent
      link="base_link" />
    <child
      link="revolute_link" />
    <axis
      xyz="-1 0 0" />
    <limit
      lower="-3.14"
      upper="3.14"
      effort="169"
      velocity="1.57" />
  </joint>
</robot>