<?xml version="1.0" encoding="utf-8"?>
<!-- This URDF was automatically created by SolidWorks to URDF Exporter! Originally created by Stephen Brawner (brawner@gmail.com) 
     Commit Version: 1.6.0-4-g7f85cfe  Build Version: 1.6.7995.38578
     For more information, please see http://wiki.ros.org/sw_urdf_exporter -->
<robot
  name="erobo3">
  <link
    name="base_link">
    <inertial>
      <origin
        xyz="-0.00228 -0.05814 -0.00089181"
        rpy="0 0 0" />
      <mass
        value="1.1786" />
      <inertia
        ixx="0.0022762"
        ixy="-7.163E-05"
        ixz="2.3775E-05"
        iyy="0.0029222"
        iyz="-3.1723E-05"
        izz="0.0022167" />
    </inertial>
    <visual>
      <origin
        xyz="0 0 0"
        rpy="0 0 0" />
      <geometry>
        <mesh
          filename="package://erob_description/meshes/erobo3/base_link.STL" />
      </geometry>
      <material
        name="">
        <color
          rgba="0.86667 0.9098 1 1" />
      </material>
    </visual>
    <collision>
      <origin
        xyz="0 0 0"
        rpy="0 0 0" />
      <geometry>
        <mesh
          filename="package://erob_description/meshes/erobo3/base_link.STL" />
      </geometry>
    </collision>
  </link>
  <link
    name="link1">
    <inertial>
      <origin
        xyz="-0.0024103 0.0057041 0.042906"
        rpy="0 0 0" />
      <mass
        value="0.26987" />
      <inertia
        ixx="0.00029683"
        ixy="5.9616E-06"
        ixz="-4.7309E-06"
        iyy="0.00028481"
        iyz="1.1582E-05"
        izz="0.00038254" />
    </inertial>
    <visual>
      <origin
        xyz="0 0 0"
        rpy="0 0 0" />
      <geometry>
        <mesh
          filename="package://erob_description/meshes/erobo3/link1.STL" />
      </geometry>
      <material
        name="">
        <color
          rgba="0.75294 0.75294 0.75294 1" />
      </material>
    </visual>
    <collision>
      <origin
        xyz="0 0 0"
        rpy="0 0 0" />
      <geometry>
        <mesh
          filename="package://erob_description/meshes/erobo3/link1.STL" />
      </geometry>
    </collision>
  </link>
  <joint
    name="joint1"
    type="revolute">
    <origin
      xyz="0 0 0"
      rpy="0 0 0" />
    <parent
      link="base_link" />
    <child
      link="link1" />
    <axis
      xyz="0 0 1" />
    <limit
      lower="-3.14"
      upper="3.14"
      effort="89"
      velocity="1.57" />
  </joint>
  <link
    name="link2">
    <inertial>
      <origin
        xyz="-0.0048043 0.11592 0.046623"
        rpy="0 0 0" />
      <mass
        value="0.95977" />
      <inertia
        ixx="0.0019004"
        ixy="3.7723E-05"
        ixz="4.7075E-07"
        iyy="0.00097497"
        iyz="6.5213E-09"
        izz="0.0020678" />
    </inertial>
    <visual>
      <origin
        xyz="0 0 0"
        rpy="0 0 0" />
      <geometry>
        <mesh
          filename="package://erob_description/meshes/erobo3/link2.STL" />
      </geometry>
      <material
        name="">
        <color
          rgba="0.79216 0.81961 0.93333 1" />
      </material>
    </visual>
    <collision>
      <origin
        xyz="0 0 0"
        rpy="0 0 0" />
      <geometry>
        <mesh
          filename="package://erob_description/meshes/erobo3/link2.STL" />
      </geometry>
    </collision>
  </link>
  <joint
    name="joint2"
    type="revolute">
    <origin
      xyz="-0.020598 0.048834 0.0435"
      rpy="1.5708 0 -2.7443" />
    <parent
      link="link1" />
    <child
      link="link2" />
    <axis
      xyz="0 0 -1" />
    <limit
      lower="-3.14"
      upper="3.14"
      effort="89"
      velocity="1.57" />
  </joint>
  <link
    name="link3">
    <inertial>
      <origin
        xyz="0.012016 0.066084 0.047955"
        rpy="0 0 0" />
      <mass
        value="0.77906" />
      <inertia
        ixx="0.0010252"
        ixy="-0.00011624"
        ixz="1.678E-06"
        iyy="0.00065704"
        iyz="4.2143E-06"
        izz="0.0012337" />
    </inertial>
    <visual>
      <origin
        xyz="0 0 0"
        rpy="0 0 0" />
      <geometry>
        <mesh
          filename="package://erob_description/meshes/erobo3/link3.STL" />
      </geometry>
      <material
        name="">
        <color
          rgba="0.75294 0.75294 0.75294 1" />
      </material>
    </visual>
    <collision>
      <origin
        xyz="0 0 0"
        rpy="0 0 0" />
      <geometry>
        <mesh
          filename="package://erob_description/meshes/erobo3/link3.STL" />
      </geometry>
    </collision>
  </link>
  <joint
    name="joint3"
    type="revolute">
    <origin
      xyz="-0.016847 0.24292 0.00043131"
      rpy="3.1416 0 -3.1416" />
    <parent
      link="link2" />
    <child
      link="link3" />
    <axis
      xyz="0 0 -1" />
    <limit
      lower="-3.14"
      upper="3.14"
      effort="89"
      velocity="1.57" />
  </joint>
  <link
    name="link4">
    <inertial>
      <origin
        xyz="0.0068449 -0.0059708 0.029196"
        rpy="0 0 0" />
      <mass
        value="0.14724" />
      <inertia
        ixx="0.00012624"
        ixy="-5.1994E-07"
        ixz="-3.2353E-08"
        iyy="0.00016231"
        iyz="7.1613E-06"
        izz="0.00011779" />
    </inertial>
    <visual>
      <origin
        xyz="0 0 0"
        rpy="0 0 0" />
      <geometry>
        <mesh
          filename="package://erob_description/meshes/erobo3/link4.STL" />
      </geometry>
      <material
        name="">
        <color
          rgba="0.75294 0.75294 0.75294 1" />
      </material>
    </visual>
    <collision>
      <origin
        xyz="0 0 0"
        rpy="0 0 0" />
      <geometry>
        <mesh
          filename="package://erob_description/meshes/erobo3/link4.STL" />
      </geometry>
    </collision>
  </link>
  <joint
    name="joint4"
    type="revolute">
    <origin
      xyz="0.05822 0.20282 0.013792"
      rpy="-3.1416 0 3.1416" />
    <parent
      link="link3" />
    <child
      link="link4" />
    <axis
      xyz="0 0 1" />
    <limit
      lower="-3.14"
      upper="3.14"
      effort="54"
      velocity="1.57" />
  </joint>
  <link
    name="link5">
    <inertial>
      <origin
        xyz="-0.0001352 0.0067778 0.038844"
        rpy="0 0 0" />
      <mass
        value="0.14724" />
      <inertia
        ixx="0.00015549"
        ixy="-1.3012E-05"
        ixz="6.5152E-06"
        iyy="0.00013201"
        iyz="-2.9713E-06"
        izz="0.00011884" />
    </inertial>
    <visual>
      <origin
        xyz="0 0 0"
        rpy="0 0 0" />
      <geometry>
        <mesh
          filename="package://erob_description/meshes/erobo3/link5.STL" />
      </geometry>
      <material
        name="">
        <color
          rgba="0.75294 0.75294 0.75294 1" />
      </material>
    </visual>
    <collision>
      <origin
        xyz="0 0 0"
        rpy="0 0 0" />
      <geometry>
        <mesh
          filename="package://erob_description/meshes/erobo3/link5.STL" />
      </geometry>
    </collision>
  </link>
  <joint
    name="joint5"
    type="revolute">
    <origin
      xyz="-0.00038992 0.038997 0.047001"
      rpy="-1.5869 -1.5708 0.028381" />
    <parent
      link="link4" />
    <child
      link="link5" />
    <axis
      xyz="0 0 1" />
    <limit
      lower="-3.14"
      upper="3.14"
      effort="34"
      velocity="1.57" />
  </joint>
  <link
    name="link6">
    <inertial>
      <origin
        xyz="0.0060193 0.00018442 -0.018323"
        rpy="0 0 0" />
      <mass
        value="0.24156" />
      <inertia
        ixx="0.00011407"
        ixy="7.9902E-07"
        ixz="2.0083E-08"
        iyy="0.00011608"
        iyz="5.7355E-08"
        izz="0.0001913" />
    </inertial>
    <visual>
      <origin
        xyz="0 0 0"
        rpy="0 0 0" />
      <geometry>
        <mesh
          filename="package://erob_description/meshes/erobo3/link6.STL" />
      </geometry>
      <material
        name="">
        <color
          rgba="0.8902 0.8902 0.91373 1" />
      </material>
    </visual>
    <collision>
      <origin
        xyz="0 0 0"
        rpy="0 0 0" />
      <geometry>
        <mesh
          filename="package://erob_description/meshes/erobo3/link6.STL" />
      </geometry>
    </collision>
  </link>
  <joint
    name="joint6"
    type="revolute">
    <origin
      xyz="0.066182 -0.029603 0.046998"
      rpy="1.5708 0.011172 1.1502" />
    <parent
      link="link5" />
    <child
      link="link6" />
    <axis
      xyz="0 0 -1" />
    <limit
      lower="-3.14"
      upper="3.14"
      effort="34"
      velocity="1.57" />
  </joint>
</robot>